Sleeping for 5 seconds
Handling submission 9ozptm by swaggyduck0121
  Link: https://discord.gg/2B7vy86
  Found no invite corresponding with the code 2B7vy86 - replying...
Traceback (most recent call last):
  File "/home/debian/DiscordServers/discordservers.py", line 408, in <module>
    handle_submission(submission)
  File "/home/debian/DiscordServers/discordservers.py", line 242, in handle_submission
    reply_and_delete_submission(subm)
  File "/home/debian/DiscordServers/discordservers.py", line 159, in reply_and_delete_submission
    comment = subm.reply(msg)
  File "/usr/local/lib/python3.6/site-packages/praw/models/reddit/mixins/replyable.py", line 26, in reply
    return self._reddit.post(API_PATH['comment'], data=data)[0]
  File "/usr/local/lib/python3.6/site-packages/praw/reddit.py", line 465, in post
    params=params)
  File "/usr/local/lib/python3.6/site-packages/praw/reddit.py", line 506, in request
    params=params)
  File "/usr/local/lib/python3.6/site-packages/prawcore/sessions.py", line 185, in request
    params=params, url=url)
  File "/usr/local/lib/python3.6/site-packages/prawcore/sessions.py", line 128, in _request_with_retries
    retries, saved_exception, url)
  File "/usr/local/lib/python3.6/site-packages/prawcore/sessions.py", line 94, in _do_retry
    params=params, url=url, retries=retries - 1)
  File "/usr/local/lib/python3.6/site-packages/prawcore/sessions.py", line 128, in _request_with_retries
    retries, saved_exception, url)
  File "/usr/local/lib/python3.6/site-packages/prawcore/sessions.py", line 94, in _do_retry
    params=params, url=url, retries=retries - 1)
  File "/usr/local/lib/python3.6/site-packages/prawcore/sessions.py", line 130, in _request_with_retries
    raise self.STATUS_EXCEPTIONS[response.status_code](response)
prawcore.exceptions.ServerError: received 500 HTTP response
